<robot name = "robot">
    <link name="link0">
        <inertial>
            <origin xyz="0 0 5" rpy="0 0 0"/>
            <mass value="1" />
            <inertia ixx="100" ixy="0" ixz="0" iyy="100" iyz="0" izz="100" />
        </inertial>
        <visual>
            <origin xyz="0 0 5" rpy="0 0 0"/>
            <geometry>
            <box size="0.6933278469902298 0.7312448349596687 0.7489278717061172" />
            </geometry>
            <material name="Green">
                <color rgba="0 0.4 0 1.0"/>
            </material>
        </visual>
        <collision>
            <origin xyz="0 0 5" rpy="0 0 0"/>
            <geometry>
            <box size="0.6933278469902298 0.7312448349596687 0.7489278717061172" />
            </geometry>
        </collision>
    </link>
    <joint name="link0_link1" type="revolute">
       <parent link="link0"/>
       <child  link="link1"/>
       <origin rpy="0 0 0" xyz="0 0.5 5" />
       <axis xyz="0 1 0"/>
       <limit effort="0.0" lower="-3.14159" upper="3.14159" velocity="0.0"/>
    </joint>
    <link name="link1">
        <inertial>
            <origin xyz="0 0.36562241747983437 0" rpy="0 0 0"/>
            <mass value="1" />
            <inertia ixx="100" ixy="0" ixz="0" iyy="100" iyz="0" izz="100" />
        </inertial>
        <visual>
            <origin xyz="0 0.36562241747983437 0" rpy="0 0 0"/>
            <geometry>
            <box size="0.5325229988142806 0.7082194612441858 0.6454139427839001" />
            </geometry>
            <material name="Cyan">
                 <color rgba="0 1.0 1.0 1.0"/>
            </material>
        </visual>
        <collision>
            <origin xyz="0 0.36562241747983437 0" rpy="0 0 0"/>
            <geometry>
            <box size="0.5325229988142806 0.7082194612441858 0.6454139427839001" />
            </geometry>
        </collision>
    </link>
    <joint name="link1_link2" type="revolute">
       <parent link="link1"/>
       <child  link="link2"/>
       <origin rpy="0 0 0" xyz="0 0.3541097306220929 0.32270697139195004" />
       <axis xyz="0 0 1"/>
       <limit effort="0.0" lower="-3.14159" upper="3.14159" velocity="0.0"/>
    </joint>
    <link name="link2">
        <inertial>
            <origin xyz="0 0 0.32270697139195004" rpy="0 0 0"/>
            <mass value="1" />
            <inertia ixx="100" ixy="0" ixz="0" iyy="100" iyz="0" izz="100" />
        </inertial>
        <visual>
            <origin xyz="0 0 0.32270697139195004" rpy="0 0 0"/>
            <geometry>
            <box size="0.946203144913474 0.8151402123015146 0.5351838715655561" />
            </geometry>
            <material name="Green">
                <color rgba="0 0.4 0 1.0"/>
            </material>
        </visual>
        <collision>
            <origin xyz="0 0 0.32270697139195004" rpy="0 0 0"/>
            <geometry>
            <box size="0.946203144913474 0.8151402123015146 0.5351838715655561" />
            </geometry>
        </collision>
    </link>
    <joint name="link2_link3" type="revolute">
       <parent link="link2"/>
       <child  link="link3"/>
       <origin rpy="0 0 0" xyz="0 0.473101572456737 0.26759193578277807" />
       <axis xyz="0 1 0"/>
       <limit effort="0.0" lower="-3.14159" upper="3.14159" velocity="0.0"/>
    </joint>
    <link name="link3">
        <inertial>
            <origin xyz="0 0.4075701061507573 0" rpy="0 0 0"/>
            <mass value="1" />
            <inertia ixx="100" ixy="0" ixz="0" iyy="100" iyz="0" izz="100" />
        </inertial>
        <visual>
            <origin xyz="0 0.4075701061507573 0" rpy="0 0 0"/>
            <geometry>
            <box size="0.9558104739163238 0.9720190526973506 0.7299525561491941" />
            </geometry>
            <material name="Green">
                <color rgba="0 0.4 0 1.0"/>
            </material>
        </visual>
        <collision>
            <origin xyz="0 0.4075701061507573 0" rpy="0 0 0"/>
            <geometry>
            <box size="0.9558104739163238 0.9720190526973506 0.7299525561491941" />
            </geometry>
        </collision>
    </link>
</robot>