<robot name = "robot">
    <link name="link0">
        <inertial>
            <origin xyz="0 0 3" rpy="0 0 0"/>
            <mass value="1" />
            <inertia ixx="100" ixy="0" ixz="0" iyy="100" iyz="0" izz="100" />
        </inertial>
        <visual>
            <origin xyz="0 0 3" rpy="0 0 0"/>
            <geometry>
            <box size="0.5620404076941705 0.2296378464009881 0.8134558433025307" />
            </geometry>
            <material name="Green">
                <color rgba="0 0.4 0 1.0"/>
            </material>
        </visual>
        <collision>
            <origin xyz="0 0 3" rpy="0 0 0"/>
            <geometry>
            <box size="0.5620404076941705 0.2296378464009881 0.8134558433025307" />
            </geometry>
        </collision>
    </link>
    <joint name="link0_link1" type="revolute">
       <parent link="link0"/>
       <child  link="link1"/>
       <origin rpy="0 0 0" xyz="0 -0.28102020384708526 3" />
       <axis xyz="0 1 0"/>
       <limit effort="0.0" lower="-3.14159" upper="3.14159" velocity="0.0"/>
    </joint>
    <link name="link1">
        <inertial>
            <origin xyz="0 0.028704730800123514 0" rpy="0 0 0"/>
            <mass value="1" />
            <inertia ixx="100" ixy="0" ixz="0" iyy="100" iyz="0" izz="100" />
        </inertial>
        <visual>
            <origin xyz="0 0.028704730800123514 0" rpy="0 0 0"/>
            <geometry>
            <box size="0.8071050574498323 0.8707873745002582 0.36622761764772194" />
            </geometry>
            <material name="Green">
                <color rgba="0 0.4 0 1.0"/>
            </material>
        </visual>
        <collision>
            <origin xyz="0 0.028704730800123514 0" rpy="0 0 0"/>
            <geometry>
            <box size="0.8071050574498323 0.8707873745002582 0.36622761764772194" />
            </geometry>
        </collision>
    </link>
    <joint name="link1_link2" type="revolute">
       <parent link="link1"/>
       <child  link="link2"/>
       <origin rpy="0 0 0" xyz="-0.40355252872491615 -0.4353936872501291 0" />
       <axis xyz="1 0 0"/>
       <limit effort="0.0" lower="-3.14159" upper="3.14159" velocity="0.0"/>
    </joint>
    <link name="link2">
        <inertial>
            <origin xyz="0.10088813218122904 0 0" rpy="0 0 0"/>
            <mass value="1" />
            <inertia ixx="100" ixy="0" ixz="0" iyy="100" iyz="0" izz="100" />
        </inertial>
        <visual>
            <origin xyz="0.10088813218122904 0 0" rpy="0 0 0"/>
            <geometry>
            <box size="0.6713567582211156 0.1381732929702297 0.6132243551390095" />
            </geometry>
            <material name="Green">
                <color rgba="0 0.4 0 1.0"/>
            </material>
        </visual>
        <collision>
            <origin xyz="0.10088813218122904 0 0" rpy="0 0 0"/>
            <geometry>
            <box size="0.6713567582211156 0.1381732929702297 0.6132243551390095" />
            </geometry>
        </collision>
    </link>
</robot>